2024-01-28 07:11:41,057 INFO    Thread-12 (_run_job):94756 [wandb_setup.py:_flush():76] Current SDK version is 0.16.1
2024-01-28 07:11:41,057 INFO    Thread-12 (_run_job):94756 [wandb_setup.py:_flush():76] Configure stats pid to 94756
2024-01-28 07:11:41,057 INFO    Thread-12 (_run_job):94756 [wandb_setup.py:_flush():76] Loading settings from /Users/adamimos/.config/wandb/settings
2024-01-28 07:11:41,057 INFO    Thread-12 (_run_job):94756 [wandb_setup.py:_flush():76] Loading settings from /Users/adamimos/Documents/GitHub/epsilon-transformers/wandb/settings
2024-01-28 07:11:41,057 INFO    Thread-12 (_run_job):94756 [wandb_setup.py:_flush():76] Loading settings from environment variables: {'project': 'RRXOR_initial_sweep', 'entity': 'adamimos', 'root_dir': '/Users/adamimos/Documents/GitHub/epsilon-transformers', 'run_id': '85bwtchj', 'sweep_param_path': '/Users/adamimos/Documents/GitHub/epsilon-transformers/wandb/sweep-gd9d1yiu/config-85bwtchj.yaml', 'sweep_id': 'gd9d1yiu'}
2024-01-28 07:11:41,057 INFO    Thread-12 (_run_job):94756 [wandb_setup.py:_flush():76] Applying setup settings: {'_disable_service': False}
2024-01-28 07:11:41,057 INFO    Thread-12 (_run_job):94756 [wandb_setup.py:_flush():76] Inferring run settings from compute environment: {'program_relpath': 'test.py', 'program_abspath': '/Users/adamimos/Documents/GitHub/epsilon-transformers/test.py', 'program': '/Users/adamimos/Documents/GitHub/epsilon-transformers/./test.py'}
2024-01-28 07:11:41,057 INFO    Thread-12 (_run_job):94756 [wandb_init.py:_log_setup():524] Logging user logs to /Users/adamimos/Documents/GitHub/epsilon-transformers/wandb/run-20240128_071141-85bwtchj/logs/debug.log
2024-01-28 07:11:41,057 INFO    Thread-12 (_run_job):94756 [wandb_init.py:_log_setup():525] Logging internal logs to /Users/adamimos/Documents/GitHub/epsilon-transformers/wandb/run-20240128_071141-85bwtchj/logs/debug-internal.log
2024-01-28 07:11:41,058 INFO    Thread-12 (_run_job):94756 [wandb_init.py:init():564] calling init triggers
2024-01-28 07:11:41,058 INFO    Thread-12 (_run_job):94756 [wandb_init.py:init():571] wandb.init called with sweep_config: {'act_fn': 'relu', 'attention_dir': 'causal', 'attn_only': False, 'batch_size': 4096, 'd_head': 8, 'd_mlp': 64, 'd_model': 64, 'd_vocab': 2, 'init_weights': True, 'learning_rate': 0.001, 'n_ctx': 10, 'n_heads': 1, 'n_layers': 256, 'normalization_type': None, 'num_epochs': 200, 'num_sequences': 1000, 'optimizer': 'adam', 'seed': 42, 'sequence_length': 500, 'use_attn_scale': True, 'weight_decay': 0.08}
config: {}
2024-01-28 07:11:41,058 INFO    Thread-12 (_run_job):94756 [wandb_init.py:init():614] starting backend
2024-01-28 07:11:41,058 INFO    Thread-12 (_run_job):94756 [wandb_init.py:init():618] setting up manager
2024-01-28 07:11:41,066 INFO    Thread-12 (_run_job):94756 [backend.py:_multiprocessing_setup():105] multiprocessing start_methods=spawn,fork,forkserver, using: spawn
2024-01-28 07:11:41,066 INFO    Thread-12 (_run_job):94756 [wandb_init.py:init():624] backend started and connected
2024-01-28 07:11:41,075 INFO    Thread-12 (_run_job):94756 [wandb_run.py:_config_callback():1342] config_cb None None {'act_fn': 'relu', 'attention_dir': 'causal', 'attn_only': False, 'batch_size': 4096, 'd_head': 8, 'd_mlp': 64, 'd_model': 64, 'd_vocab': 2, 'init_weights': True, 'learning_rate': 0.001, 'n_ctx': 10, 'n_heads': 1, 'n_layers': 256, 'normalization_type': None, 'num_epochs': 200, 'num_sequences': 1000, 'optimizer': 'adam', 'seed': 42, 'sequence_length': 500, 'use_attn_scale': True, 'weight_decay': 0.08}
2024-01-28 07:11:41,084 INFO    Thread-12 (_run_job):94756 [wandb_init.py:init():716] updated telemetry
2024-01-28 07:11:41,121 INFO    Thread-12 (_run_job):94756 [wandb_init.py:init():749] communicating run to backend with 90.0 second timeout
2024-01-28 07:11:41,390 INFO    Thread-12 (_run_job):94756 [wandb_run.py:_on_init():2254] communicating current version
2024-01-28 07:11:41,505 INFO    Thread-12 (_run_job):94756 [wandb_run.py:_on_init():2263] got version response upgrade_message: "wandb version 0.16.2 is available!  To upgrade, please run:\n $ pip install wandb --upgrade"

2024-01-28 07:11:41,506 INFO    Thread-12 (_run_job):94756 [wandb_init.py:init():800] starting run threads in backend
2024-01-28 07:11:43,010 INFO    Thread-12 (_run_job):94756 [wandb_run.py:_console_start():2233] atexit reg
2024-01-28 07:11:43,010 INFO    Thread-12 (_run_job):94756 [wandb_run.py:_redirect():2088] redirect: wrap_raw
2024-01-28 07:11:43,010 INFO    Thread-12 (_run_job):94756 [wandb_run.py:_redirect():2153] Wrapping output streams.
2024-01-28 07:11:43,010 INFO    Thread-12 (_run_job):94756 [wandb_run.py:_redirect():2178] Redirects installed.
2024-01-28 07:11:43,011 INFO    Thread-12 (_run_job):94756 [wandb_init.py:init():841] run started, returning control to user process
2024-01-28 19:54:50,018 INFO    Thread-1 (_heartbeat):94756 [retry.py:__call__():172] Retry attempt failed:
Traceback (most recent call last):
  File "/Users/adamimos/anaconda3/envs/epsilon-machine/lib/python3.11/site-packages/urllib3/connection.py", line 174, in _new_conn
    conn = connection.create_connection(
           ^^^^^^^^^^^^^^^^^^^^^^^^^^^^^
  File "/Users/adamimos/anaconda3/envs/epsilon-machine/lib/python3.11/site-packages/urllib3/util/connection.py", line 72, in create_connection
    for res in socket.getaddrinfo(host, port, family, socket.SOCK_STREAM):
               ^^^^^^^^^^^^^^^^^^^^^^^^^^^^^^^^^^^^^^^^^^^^^^^^^^^^^^^^^^
  File "/Users/adamimos/anaconda3/envs/epsilon-machine/lib/python3.11/socket.py", line 962, in getaddrinfo
    for res in _socket.getaddrinfo(host, port, family, type, proto, flags):
               ^^^^^^^^^^^^^^^^^^^^^^^^^^^^^^^^^^^^^^^^^^^^^^^^^^^^^^^^^^^
socket.gaierror: [Errno 8] nodename nor servname provided, or not known

During handling of the above exception, another exception occurred:

Traceback (most recent call last):
  File "/Users/adamimos/anaconda3/envs/epsilon-machine/lib/python3.11/site-packages/urllib3/connectionpool.py", line 715, in urlopen
    httplib_response = self._make_request(
                       ^^^^^^^^^^^^^^^^^^^
  File "/Users/adamimos/anaconda3/envs/epsilon-machine/lib/python3.11/site-packages/urllib3/connectionpool.py", line 404, in _make_request
    self._validate_conn(conn)
  File "/Users/adamimos/anaconda3/envs/epsilon-machine/lib/python3.11/site-packages/urllib3/connectionpool.py", line 1058, in _validate_conn
    conn.connect()
  File "/Users/adamimos/anaconda3/envs/epsilon-machine/lib/python3.11/site-packages/urllib3/connection.py", line 363, in connect
    self.sock = conn = self._new_conn()
                       ^^^^^^^^^^^^^^^^
  File "/Users/adamimos/anaconda3/envs/epsilon-machine/lib/python3.11/site-packages/urllib3/connection.py", line 186, in _new_conn
    raise NewConnectionError(
urllib3.exceptions.NewConnectionError: <urllib3.connection.HTTPSConnection object at 0x2de076110>: Failed to establish a new connection: [Errno 8] nodename nor servname provided, or not known

During handling of the above exception, another exception occurred:

Traceback (most recent call last):
  File "/Users/adamimos/anaconda3/envs/epsilon-machine/lib/python3.11/site-packages/requests/adapters.py", line 486, in send
    resp = conn.urlopen(
           ^^^^^^^^^^^^^
  File "/Users/adamimos/anaconda3/envs/epsilon-machine/lib/python3.11/site-packages/urllib3/connectionpool.py", line 799, in urlopen
    retries = retries.increment(
              ^^^^^^^^^^^^^^^^^^
  File "/Users/adamimos/anaconda3/envs/epsilon-machine/lib/python3.11/site-packages/urllib3/util/retry.py", line 592, in increment
    raise MaxRetryError(_pool, url, error or ResponseError(cause))
urllib3.exceptions.MaxRetryError: HTTPSConnectionPool(host='api.wandb.ai', port=443): Max retries exceeded with url: /graphql (Caused by NewConnectionError('<urllib3.connection.HTTPSConnection object at 0x2de076110>: Failed to establish a new connection: [Errno 8] nodename nor servname provided, or not known'))

During handling of the above exception, another exception occurred:

Traceback (most recent call last):
  File "/Users/adamimos/anaconda3/envs/epsilon-machine/lib/python3.11/site-packages/wandb/sdk/lib/retry.py", line 131, in __call__
    result = self._call_fn(*args, **kwargs)
             ^^^^^^^^^^^^^^^^^^^^^^^^^^^^^^
  File "/Users/adamimos/anaconda3/envs/epsilon-machine/lib/python3.11/site-packages/wandb/sdk/internal/internal_api.py", line 369, in execute
    return self.client.execute(*args, **kwargs)  # type: ignore
           ^^^^^^^^^^^^^^^^^^^^^^^^^^^^^^^^^^^^
  File "/Users/adamimos/anaconda3/envs/epsilon-machine/lib/python3.11/site-packages/wandb/vendor/gql-0.2.0/wandb_gql/client.py", line 52, in execute
    result = self._get_result(document, *args, **kwargs)
             ^^^^^^^^^^^^^^^^^^^^^^^^^^^^^^^^^^^^^^^^^^^
  File "/Users/adamimos/anaconda3/envs/epsilon-machine/lib/python3.11/site-packages/wandb/vendor/gql-0.2.0/wandb_gql/client.py", line 60, in _get_result
    return self.transport.execute(document, *args, **kwargs)
           ^^^^^^^^^^^^^^^^^^^^^^^^^^^^^^^^^^^^^^^^^^^^^^^^^
  File "/Users/adamimos/anaconda3/envs/epsilon-machine/lib/python3.11/site-packages/wandb/sdk/lib/gql_request.py", line 58, in execute
    request = self.session.post(self.url, **post_args)
              ^^^^^^^^^^^^^^^^^^^^^^^^^^^^^^^^^^^^^^^^
  File "/Users/adamimos/anaconda3/envs/epsilon-machine/lib/python3.11/site-packages/requests/sessions.py", line 637, in post
    return self.request("POST", url, data=data, json=json, **kwargs)
           ^^^^^^^^^^^^^^^^^^^^^^^^^^^^^^^^^^^^^^^^^^^^^^^^^^^^^^^^^
  File "/Users/adamimos/anaconda3/envs/epsilon-machine/lib/python3.11/site-packages/requests/sessions.py", line 589, in request
    resp = self.send(prep, **send_kwargs)
           ^^^^^^^^^^^^^^^^^^^^^^^^^^^^^^
  File "/Users/adamimos/anaconda3/envs/epsilon-machine/lib/python3.11/site-packages/requests/sessions.py", line 703, in send
    r = adapter.send(request, **kwargs)
        ^^^^^^^^^^^^^^^^^^^^^^^^^^^^^^^
  File "/Users/adamimos/anaconda3/envs/epsilon-machine/lib/python3.11/site-packages/requests/adapters.py", line 519, in send
    raise ConnectionError(e, request=request)
requests.exceptions.ConnectionError: HTTPSConnectionPool(host='api.wandb.ai', port=443): Max retries exceeded with url: /graphql (Caused by NewConnectionError('<urllib3.connection.HTTPSConnection object at 0x2de076110>: Failed to establish a new connection: [Errno 8] nodename nor servname provided, or not known'))
2024-01-29 09:16:12,581 INFO    Thread-1 (_heartbeat):94756 [retry.py:__call__():172] Retry attempt failed:
Traceback (most recent call last):
  File "/Users/adamimos/anaconda3/envs/epsilon-machine/lib/python3.11/site-packages/urllib3/connection.py", line 174, in _new_conn
    conn = connection.create_connection(
           ^^^^^^^^^^^^^^^^^^^^^^^^^^^^^
  File "/Users/adamimos/anaconda3/envs/epsilon-machine/lib/python3.11/site-packages/urllib3/util/connection.py", line 72, in create_connection
    for res in socket.getaddrinfo(host, port, family, socket.SOCK_STREAM):
               ^^^^^^^^^^^^^^^^^^^^^^^^^^^^^^^^^^^^^^^^^^^^^^^^^^^^^^^^^^
  File "/Users/adamimos/anaconda3/envs/epsilon-machine/lib/python3.11/socket.py", line 962, in getaddrinfo
    for res in _socket.getaddrinfo(host, port, family, type, proto, flags):
               ^^^^^^^^^^^^^^^^^^^^^^^^^^^^^^^^^^^^^^^^^^^^^^^^^^^^^^^^^^^
socket.gaierror: [Errno 8] nodename nor servname provided, or not known

During handling of the above exception, another exception occurred:

Traceback (most recent call last):
  File "/Users/adamimos/anaconda3/envs/epsilon-machine/lib/python3.11/site-packages/urllib3/connectionpool.py", line 715, in urlopen
    httplib_response = self._make_request(
                       ^^^^^^^^^^^^^^^^^^^
  File "/Users/adamimos/anaconda3/envs/epsilon-machine/lib/python3.11/site-packages/urllib3/connectionpool.py", line 404, in _make_request
    self._validate_conn(conn)
  File "/Users/adamimos/anaconda3/envs/epsilon-machine/lib/python3.11/site-packages/urllib3/connectionpool.py", line 1058, in _validate_conn
    conn.connect()
  File "/Users/adamimos/anaconda3/envs/epsilon-machine/lib/python3.11/site-packages/urllib3/connection.py", line 363, in connect
    self.sock = conn = self._new_conn()
                       ^^^^^^^^^^^^^^^^
  File "/Users/adamimos/anaconda3/envs/epsilon-machine/lib/python3.11/site-packages/urllib3/connection.py", line 186, in _new_conn
    raise NewConnectionError(
urllib3.exceptions.NewConnectionError: <urllib3.connection.HTTPSConnection object at 0x2ca4a7850>: Failed to establish a new connection: [Errno 8] nodename nor servname provided, or not known

During handling of the above exception, another exception occurred:

Traceback (most recent call last):
  File "/Users/adamimos/anaconda3/envs/epsilon-machine/lib/python3.11/site-packages/requests/adapters.py", line 486, in send
    resp = conn.urlopen(
           ^^^^^^^^^^^^^
  File "/Users/adamimos/anaconda3/envs/epsilon-machine/lib/python3.11/site-packages/urllib3/connectionpool.py", line 799, in urlopen
    retries = retries.increment(
              ^^^^^^^^^^^^^^^^^^
  File "/Users/adamimos/anaconda3/envs/epsilon-machine/lib/python3.11/site-packages/urllib3/util/retry.py", line 592, in increment
    raise MaxRetryError(_pool, url, error or ResponseError(cause))
urllib3.exceptions.MaxRetryError: HTTPSConnectionPool(host='api.wandb.ai', port=443): Max retries exceeded with url: /graphql (Caused by NewConnectionError('<urllib3.connection.HTTPSConnection object at 0x2ca4a7850>: Failed to establish a new connection: [Errno 8] nodename nor servname provided, or not known'))

During handling of the above exception, another exception occurred:

Traceback (most recent call last):
  File "/Users/adamimos/anaconda3/envs/epsilon-machine/lib/python3.11/site-packages/wandb/sdk/lib/retry.py", line 131, in __call__
    result = self._call_fn(*args, **kwargs)
             ^^^^^^^^^^^^^^^^^^^^^^^^^^^^^^
  File "/Users/adamimos/anaconda3/envs/epsilon-machine/lib/python3.11/site-packages/wandb/sdk/internal/internal_api.py", line 369, in execute
    return self.client.execute(*args, **kwargs)  # type: ignore
           ^^^^^^^^^^^^^^^^^^^^^^^^^^^^^^^^^^^^
  File "/Users/adamimos/anaconda3/envs/epsilon-machine/lib/python3.11/site-packages/wandb/vendor/gql-0.2.0/wandb_gql/client.py", line 52, in execute
    result = self._get_result(document, *args, **kwargs)
             ^^^^^^^^^^^^^^^^^^^^^^^^^^^^^^^^^^^^^^^^^^^
  File "/Users/adamimos/anaconda3/envs/epsilon-machine/lib/python3.11/site-packages/wandb/vendor/gql-0.2.0/wandb_gql/client.py", line 60, in _get_result
    return self.transport.execute(document, *args, **kwargs)
           ^^^^^^^^^^^^^^^^^^^^^^^^^^^^^^^^^^^^^^^^^^^^^^^^^
  File "/Users/adamimos/anaconda3/envs/epsilon-machine/lib/python3.11/site-packages/wandb/sdk/lib/gql_request.py", line 58, in execute
    request = self.session.post(self.url, **post_args)
              ^^^^^^^^^^^^^^^^^^^^^^^^^^^^^^^^^^^^^^^^
  File "/Users/adamimos/anaconda3/envs/epsilon-machine/lib/python3.11/site-packages/requests/sessions.py", line 637, in post
    return self.request("POST", url, data=data, json=json, **kwargs)
           ^^^^^^^^^^^^^^^^^^^^^^^^^^^^^^^^^^^^^^^^^^^^^^^^^^^^^^^^^
  File "/Users/adamimos/anaconda3/envs/epsilon-machine/lib/python3.11/site-packages/requests/sessions.py", line 589, in request
    resp = self.send(prep, **send_kwargs)
           ^^^^^^^^^^^^^^^^^^^^^^^^^^^^^^
  File "/Users/adamimos/anaconda3/envs/epsilon-machine/lib/python3.11/site-packages/requests/sessions.py", line 703, in send
    r = adapter.send(request, **kwargs)
        ^^^^^^^^^^^^^^^^^^^^^^^^^^^^^^^
  File "/Users/adamimos/anaconda3/envs/epsilon-machine/lib/python3.11/site-packages/requests/adapters.py", line 519, in send
    raise ConnectionError(e, request=request)
requests.exceptions.ConnectionError: HTTPSConnectionPool(host='api.wandb.ai', port=443): Max retries exceeded with url: /graphql (Caused by NewConnectionError('<urllib3.connection.HTTPSConnection object at 0x2ca4a7850>: Failed to establish a new connection: [Errno 8] nodename nor servname provided, or not known'))
