2024-01-18 19:36:19,735 INFO    Thread-12 (_run_job):56485 [wandb_setup.py:_flush():76] Current SDK version is 0.16.1
2024-01-18 19:36:19,736 INFO    Thread-12 (_run_job):56485 [wandb_setup.py:_flush():76] Configure stats pid to 56485
2024-01-18 19:36:19,736 INFO    Thread-12 (_run_job):56485 [wandb_setup.py:_flush():76] Loading settings from /Users/adamimos/.config/wandb/settings
2024-01-18 19:36:19,736 INFO    Thread-12 (_run_job):56485 [wandb_setup.py:_flush():76] Loading settings from /Users/adamimos/Documents/GitHub/epsilon-transformers/wandb/settings
2024-01-18 19:36:19,736 INFO    Thread-12 (_run_job):56485 [wandb_setup.py:_flush():76] Loading settings from environment variables: {'project': 'epsilon-transformer', 'entity': 'adamimos', 'root_dir': '/Users/adamimos/Documents/GitHub/epsilon-transformers', 'run_id': 'ipcduro6', 'sweep_param_path': '/Users/adamimos/Documents/GitHub/epsilon-transformers/wandb/sweep-h058ahyt/config-ipcduro6.yaml', 'sweep_id': 'h058ahyt'}
2024-01-18 19:36:19,736 INFO    Thread-12 (_run_job):56485 [wandb_setup.py:_flush():76] Applying setup settings: {'_disable_service': False}
2024-01-18 19:36:19,736 INFO    Thread-12 (_run_job):56485 [wandb_setup.py:_flush():76] Inferring run settings from compute environment: {'program': '<python with no main file>'}
2024-01-18 19:36:19,736 INFO    Thread-12 (_run_job):56485 [wandb_init.py:_log_setup():524] Logging user logs to /Users/adamimos/Documents/GitHub/epsilon-transformers/wandb/run-20240118_193619-ipcduro6/logs/debug.log
2024-01-18 19:36:19,736 INFO    Thread-12 (_run_job):56485 [wandb_init.py:_log_setup():525] Logging internal logs to /Users/adamimos/Documents/GitHub/epsilon-transformers/wandb/run-20240118_193619-ipcduro6/logs/debug-internal.log
2024-01-18 19:36:19,736 INFO    Thread-12 (_run_job):56485 [wandb_init.py:_jupyter_setup():470] configuring jupyter hooks <wandb.sdk.wandb_init._WandbInit object at 0x2d6d7d810>
2024-01-18 19:36:19,736 INFO    Thread-12 (_run_job):56485 [wandb_init.py:init():564] calling init triggers
2024-01-18 19:36:19,736 INFO    Thread-12 (_run_job):56485 [wandb_init.py:init():571] wandb.init called with sweep_config: {'learning_rate': 1e-05, 'weight_decay': 0.0001}
config: {}
2024-01-18 19:36:19,737 INFO    Thread-12 (_run_job):56485 [wandb_init.py:init():614] starting backend
2024-01-18 19:36:19,737 INFO    Thread-12 (_run_job):56485 [wandb_init.py:init():618] setting up manager
2024-01-18 19:36:19,742 INFO    Thread-12 (_run_job):56485 [backend.py:_multiprocessing_setup():105] multiprocessing start_methods=spawn,fork,forkserver, using: spawn
2024-01-18 19:36:19,742 INFO    Thread-12 (_run_job):56485 [wandb_init.py:init():624] backend started and connected
2024-01-18 19:36:19,760 INFO    Thread-12 (_run_job):56485 [wandb_run.py:_config_callback():1342] config_cb None None {'learning_rate': 1e-05, 'weight_decay': 0.0001}
2024-01-18 19:36:19,766 INFO    Thread-12 (_run_job):56485 [wandb_run.py:_label_probe_notebook():1294] probe notebook
2024-01-18 19:36:19,766 INFO    Thread-12 (_run_job):56485 [wandb_run.py:_label_probe_notebook():1304] Unable to probe notebook: 'NoneType' object has no attribute 'get'
2024-01-18 19:36:19,766 INFO    Thread-12 (_run_job):56485 [wandb_init.py:init():716] updated telemetry
2024-01-18 19:36:19,788 INFO    Thread-12 (_run_job):56485 [wandb_init.py:init():749] communicating run to backend with 90.0 second timeout
2024-01-18 19:36:20,025 INFO    Thread-12 (_run_job):56485 [wandb_run.py:_on_init():2254] communicating current version
2024-01-18 19:36:20,097 INFO    Thread-12 (_run_job):56485 [wandb_run.py:_on_init():2263] got version response upgrade_message: "wandb version 0.16.2 is available!  To upgrade, please run:\n $ pip install wandb --upgrade"

2024-01-18 19:36:20,097 INFO    Thread-12 (_run_job):56485 [wandb_init.py:init():800] starting run threads in backend
2024-01-18 19:36:21,754 INFO    Thread-12 (_run_job):56485 [wandb_run.py:_console_start():2233] atexit reg
2024-01-18 19:36:21,754 INFO    Thread-12 (_run_job):56485 [wandb_run.py:_redirect():2088] redirect: wrap_raw
2024-01-18 19:36:21,754 INFO    Thread-12 (_run_job):56485 [wandb_run.py:_redirect():2153] Wrapping output streams.
2024-01-18 19:36:21,754 INFO    Thread-12 (_run_job):56485 [wandb_run.py:_redirect():2178] Redirects installed.
2024-01-18 19:36:21,754 INFO    Thread-12 (_run_job):56485 [wandb_init.py:init():841] run started, returning control to user process
2024-01-18 19:45:00,557 INFO    MainThread:56485 [jupyter.py:save_ipynb():373] not saving jupyter notebook
2024-01-18 19:45:00,557 INFO    MainThread:56485 [wandb_init.py:_pause_backend():435] pausing backend
2024-01-18 19:45:05,515 INFO    Thread-12 (_run_job):56485 [wandb_run.py:_finish():1962] finishing run adamimos/epsilon-transformer/ipcduro6
2024-01-18 19:45:05,516 INFO    Thread-12 (_run_job):56485 [jupyter.py:save_history():445] not saving jupyter history
2024-01-18 19:45:05,516 INFO    Thread-12 (_run_job):56485 [jupyter.py:save_ipynb():373] not saving jupyter notebook
2024-01-18 19:45:05,516 INFO    Thread-12 (_run_job):56485 [wandb_init.py:_jupyter_teardown():452] cleaning up jupyter logic
2024-01-18 19:45:05,516 INFO    Thread-12 (_run_job):56485 [wandb_run.py:_atexit_cleanup():2202] got exitcode: 1
2024-01-18 19:45:05,516 INFO    Thread-12 (_run_job):56485 [wandb_run.py:_restore():2185] restore
2024-01-18 19:45:05,516 INFO    Thread-12 (_run_job):56485 [wandb_run.py:_restore():2191] restore done
2024-01-18 19:45:07,527 ERROR   Thread-12 (_run_job):56485 [ipython.py:update():120] Socket operation on non-socket
Traceback (most recent call last):
  File "/Users/adamimos/Documents/GitHub/epsilon-transformers/epsilon_transformers/simple_transformer.py", line 310, in sweep_train
    with_positions=True
  File "/Users/adamimos/Documents/GitHub/epsilon-transformers/epsilon_transformers/simple_transformer.py", line 289, in train_hooked_model
  File "/Users/adamimos/anaconda3/envs/epsilon-machine/lib/python3.11/site-packages/wandb/sdk/lib/redirect.py", line 640, in write
    self._old_write(data)
  File "/Users/adamimos/anaconda3/envs/epsilon-machine/lib/python3.11/site-packages/ipykernel/iostream.py", line 648, in write
    self._schedule_flush()
  File "/Users/adamimos/anaconda3/envs/epsilon-machine/lib/python3.11/site-packages/ipykernel/iostream.py", line 545, in _schedule_flush
    self.pub_thread.schedule(_schedule_in_thread)
  File "/Users/adamimos/anaconda3/envs/epsilon-machine/lib/python3.11/site-packages/ipykernel/iostream.py", line 251, in schedule
    self._event_pipe.send(b"")
  File "/Users/adamimos/anaconda3/envs/epsilon-machine/lib/python3.11/site-packages/zmq/sugar/socket.py", line 696, in send
    return super().send(data, flags=flags, copy=copy, track=track)
           ^^^^^^^^^^^^^^^^^^^^^^^^^^^^^^^^^^^^^^^^^^^^^^^^^^^^^^^
  File "zmq/backend/cython/socket.pyx", line 742, in zmq.backend.cython.socket.Socket.send
  File "zmq/backend/cython/socket.pyx", line 783, in zmq.backend.cython.socket.Socket.send
  File "zmq/backend/cython/socket.pyx", line 138, in zmq.backend.cython.socket._check_closed
zmq.error.ZMQError: Socket operation on non-socket

During handling of the above exception, another exception occurred:

Traceback (most recent call last):
  File "/Users/adamimos/anaconda3/envs/epsilon-machine/lib/python3.11/site-packages/wandb/agents/pyagent.py", line 298, in _run_job
    self._function()
  File "/var/folders/gv/001yhxz1531ct7td9p0zgrh80000gn/T/ipykernel_56485/3754921824.py", line 22, in <lambda>
    wandb.agent(sweep_id, lambda: sweep_train(process, config, train_config))
                                  ^^^^^^^^^^^^^^^^^^^^^^^^^^^^^^^^^^^^^^^^^^
  File "/Users/adamimos/Documents/GitHub/epsilon-transformers/epsilon_transformers/simple_transformer.py", line 295, in sweep_train
    row = f"| {epoch+1:^5} | {avg_training_acc:^12.2%} | {loss.item():^13.4f} | {avg_overall_accuracy:^17.2%} | {avg_last_bit_accuracy:^16.2%} |"
  File "/Users/adamimos/anaconda3/envs/epsilon-machine/lib/python3.11/site-packages/wandb/sdk/wandb_run.py", line 3355, in __exit__
    traceback.print_exception(exc_type, exc_val, exc_tb)
  File "/Users/adamimos/anaconda3/envs/epsilon-machine/lib/python3.11/traceback.py", line 125, in print_exception
    te.print(file=file, chain=chain)
  File "/Users/adamimos/anaconda3/envs/epsilon-machine/lib/python3.11/traceback.py", line 1018, in print
    print(line, file=file, end="")
  File "/Users/adamimos/anaconda3/envs/epsilon-machine/lib/python3.11/site-packages/wandb/sdk/lib/redirect.py", line 640, in write
    self._old_write(data)
  File "/Users/adamimos/anaconda3/envs/epsilon-machine/lib/python3.11/site-packages/ipykernel/iostream.py", line 648, in write
    self._schedule_flush()
  File "/Users/adamimos/anaconda3/envs/epsilon-machine/lib/python3.11/site-packages/ipykernel/iostream.py", line 545, in _schedule_flush
    self.pub_thread.schedule(_schedule_in_thread)
  File "/Users/adamimos/anaconda3/envs/epsilon-machine/lib/python3.11/site-packages/ipykernel/iostream.py", line 251, in schedule
    self._event_pipe.send(b"")
  File "/Users/adamimos/anaconda3/envs/epsilon-machine/lib/python3.11/site-packages/zmq/sugar/socket.py", line 696, in send
    return super().send(data, flags=flags, copy=copy, track=track)
           ^^^^^^^^^^^^^^^^^^^^^^^^^^^^^^^^^^^^^^^^^^^^^^^^^^^^^^^
  File "zmq/backend/cython/socket.pyx", line 742, in zmq.backend.cython.socket.Socket.send
  File "zmq/backend/cython/socket.pyx", line 783, in zmq.backend.cython.socket.Socket.send
  File "zmq/backend/cython/socket.pyx", line 138, in zmq.backend.cython.socket._check_closed
zmq.error.ZMQError: Socket operation on non-socket

During handling of the above exception, another exception occurred:

Traceback (most recent call last):
  File "/Users/adamimos/anaconda3/envs/epsilon-machine/lib/python3.11/site-packages/wandb/sdk/lib/ipython.py", line 113, in update
    self._progress.value = value
    ^^^^^^^^^^^^^^^^^^^^
  File "/Users/adamimos/anaconda3/envs/epsilon-machine/lib/python3.11/site-packages/traitlets/traitlets.py", line 729, in __set__
    self.set(obj, value)
  File "/Users/adamimos/anaconda3/envs/epsilon-machine/lib/python3.11/site-packages/traitlets/traitlets.py", line 718, in set
    obj._notify_trait(self.name, old_value, new_value)
  File "/Users/adamimos/anaconda3/envs/epsilon-machine/lib/python3.11/site-packages/traitlets/traitlets.py", line 1501, in _notify_trait
    self.notify_change(
  File "/Users/adamimos/anaconda3/envs/epsilon-machine/lib/python3.11/site-packages/ipywidgets/widgets/widget.py", line 693, in notify_change
    self.send_state(key=name)
  File "/Users/adamimos/anaconda3/envs/epsilon-machine/lib/python3.11/site-packages/ipywidgets/widgets/widget.py", line 579, in send_state
    self._send(msg, buffers=buffers)
  File "/Users/adamimos/anaconda3/envs/epsilon-machine/lib/python3.11/site-packages/ipywidgets/widgets/widget.py", line 818, in _send
    self.comm.send(data=msg, buffers=buffers)
  File "/Users/adamimos/anaconda3/envs/epsilon-machine/lib/python3.11/site-packages/comm/base_comm.py", line 113, in send
    self.publish_msg(
  File "/Users/adamimos/anaconda3/envs/epsilon-machine/lib/python3.11/site-packages/ipykernel/comm/comm.py", line 36, in publish_msg
    self.kernel.session.send(
  File "/Users/adamimos/anaconda3/envs/epsilon-machine/lib/python3.11/site-packages/jupyter_client/session.py", line 863, in send
    stream.send_multipart(to_send, copy=copy)
  File "/Users/adamimos/anaconda3/envs/epsilon-machine/lib/python3.11/site-packages/ipykernel/iostream.py", line 330, in send_multipart
    return self.io_thread.send_multipart(*args, **kwargs)
           ^^^^^^^^^^^^^^^^^^^^^^^^^^^^^^^^^^^^^^^^^^^^^^
  File "/Users/adamimos/anaconda3/envs/epsilon-machine/lib/python3.11/site-packages/ipykernel/iostream.py", line 260, in send_multipart
    self.schedule(lambda: self._really_send(*args, **kwargs))
  File "/Users/adamimos/anaconda3/envs/epsilon-machine/lib/python3.11/site-packages/ipykernel/iostream.py", line 251, in schedule
    self._event_pipe.send(b"")
  File "/Users/adamimos/anaconda3/envs/epsilon-machine/lib/python3.11/site-packages/zmq/sugar/socket.py", line 696, in send
    return super().send(data, flags=flags, copy=copy, track=track)
           ^^^^^^^^^^^^^^^^^^^^^^^^^^^^^^^^^^^^^^^^^^^^^^^^^^^^^^^
  File "zmq/backend/cython/socket.pyx", line 742, in zmq.backend.cython.socket.Socket.send
  File "zmq/backend/cython/socket.pyx", line 783, in zmq.backend.cython.socket.Socket.send
  File "zmq/backend/cython/socket.pyx", line 138, in zmq.backend.cython.socket._check_closed
zmq.error.ZMQError: Socket operation on non-socket
2024-01-18 19:45:07,535 INFO    Thread-12 (_run_job):56485 [wandb_run.py:_restore():2185] restore
2024-01-18 19:45:07,535 INFO    Thread-12 (_run_job):56485 [wandb_run.py:_restore():2191] restore done
2024-01-18 19:45:08,536 ERROR   Thread-12 (_run_job):56485 [wandb_run.py:_atexit_cleanup():2223] Problem finishing run
Traceback (most recent call last):
  File "/Users/adamimos/Documents/GitHub/epsilon-transformers/epsilon_transformers/simple_transformer.py", line 310, in sweep_train
    with_positions=True
  File "/Users/adamimos/Documents/GitHub/epsilon-transformers/epsilon_transformers/simple_transformer.py", line 289, in train_hooked_model
  File "/Users/adamimos/anaconda3/envs/epsilon-machine/lib/python3.11/site-packages/wandb/sdk/lib/redirect.py", line 640, in write
    self._old_write(data)
  File "/Users/adamimos/anaconda3/envs/epsilon-machine/lib/python3.11/site-packages/ipykernel/iostream.py", line 648, in write
    self._schedule_flush()
  File "/Users/adamimos/anaconda3/envs/epsilon-machine/lib/python3.11/site-packages/ipykernel/iostream.py", line 545, in _schedule_flush
    self.pub_thread.schedule(_schedule_in_thread)
  File "/Users/adamimos/anaconda3/envs/epsilon-machine/lib/python3.11/site-packages/ipykernel/iostream.py", line 251, in schedule
    self._event_pipe.send(b"")
  File "/Users/adamimos/anaconda3/envs/epsilon-machine/lib/python3.11/site-packages/zmq/sugar/socket.py", line 696, in send
    return super().send(data, flags=flags, copy=copy, track=track)
           ^^^^^^^^^^^^^^^^^^^^^^^^^^^^^^^^^^^^^^^^^^^^^^^^^^^^^^^
  File "zmq/backend/cython/socket.pyx", line 742, in zmq.backend.cython.socket.Socket.send
  File "zmq/backend/cython/socket.pyx", line 783, in zmq.backend.cython.socket.Socket.send
  File "zmq/backend/cython/socket.pyx", line 138, in zmq.backend.cython.socket._check_closed
zmq.error.ZMQError: Socket operation on non-socket

During handling of the above exception, another exception occurred:

Traceback (most recent call last):
  File "/Users/adamimos/anaconda3/envs/epsilon-machine/lib/python3.11/site-packages/wandb/agents/pyagent.py", line 298, in _run_job
    self._function()
  File "/var/folders/gv/001yhxz1531ct7td9p0zgrh80000gn/T/ipykernel_56485/3754921824.py", line 22, in <lambda>
    wandb.agent(sweep_id, lambda: sweep_train(process, config, train_config))
                                  ^^^^^^^^^^^^^^^^^^^^^^^^^^^^^^^^^^^^^^^^^^
  File "/Users/adamimos/Documents/GitHub/epsilon-transformers/epsilon_transformers/simple_transformer.py", line 295, in sweep_train
    row = f"| {epoch+1:^5} | {avg_training_acc:^12.2%} | {loss.item():^13.4f} | {avg_overall_accuracy:^17.2%} | {avg_last_bit_accuracy:^16.2%} |"
  File "/Users/adamimos/anaconda3/envs/epsilon-machine/lib/python3.11/site-packages/wandb/sdk/wandb_run.py", line 3355, in __exit__
    traceback.print_exception(exc_type, exc_val, exc_tb)
  File "/Users/adamimos/anaconda3/envs/epsilon-machine/lib/python3.11/traceback.py", line 125, in print_exception
    te.print(file=file, chain=chain)
  File "/Users/adamimos/anaconda3/envs/epsilon-machine/lib/python3.11/traceback.py", line 1018, in print
    print(line, file=file, end="")
  File "/Users/adamimos/anaconda3/envs/epsilon-machine/lib/python3.11/site-packages/wandb/sdk/lib/redirect.py", line 640, in write
    self._old_write(data)
  File "/Users/adamimos/anaconda3/envs/epsilon-machine/lib/python3.11/site-packages/ipykernel/iostream.py", line 648, in write
    self._schedule_flush()
  File "/Users/adamimos/anaconda3/envs/epsilon-machine/lib/python3.11/site-packages/ipykernel/iostream.py", line 545, in _schedule_flush
    self.pub_thread.schedule(_schedule_in_thread)
  File "/Users/adamimos/anaconda3/envs/epsilon-machine/lib/python3.11/site-packages/ipykernel/iostream.py", line 251, in schedule
    self._event_pipe.send(b"")
  File "/Users/adamimos/anaconda3/envs/epsilon-machine/lib/python3.11/site-packages/zmq/sugar/socket.py", line 696, in send
    return super().send(data, flags=flags, copy=copy, track=track)
           ^^^^^^^^^^^^^^^^^^^^^^^^^^^^^^^^^^^^^^^^^^^^^^^^^^^^^^^
  File "zmq/backend/cython/socket.pyx", line 742, in zmq.backend.cython.socket.Socket.send
  File "zmq/backend/cython/socket.pyx", line 783, in zmq.backend.cython.socket.Socket.send
  File "zmq/backend/cython/socket.pyx", line 138, in zmq.backend.cython.socket._check_closed
zmq.error.ZMQError: Socket operation on non-socket

During handling of the above exception, another exception occurred:

Traceback (most recent call last):
  File "/Users/adamimos/anaconda3/envs/epsilon-machine/lib/python3.11/site-packages/wandb/sdk/lib/ipython.py", line 113, in update
    self._progress.value = value
    ^^^^^^^^^^^^^^^^^^^^
  File "/Users/adamimos/anaconda3/envs/epsilon-machine/lib/python3.11/site-packages/traitlets/traitlets.py", line 729, in __set__
    self.set(obj, value)
  File "/Users/adamimos/anaconda3/envs/epsilon-machine/lib/python3.11/site-packages/traitlets/traitlets.py", line 718, in set
    obj._notify_trait(self.name, old_value, new_value)
  File "/Users/adamimos/anaconda3/envs/epsilon-machine/lib/python3.11/site-packages/traitlets/traitlets.py", line 1501, in _notify_trait
    self.notify_change(
  File "/Users/adamimos/anaconda3/envs/epsilon-machine/lib/python3.11/site-packages/ipywidgets/widgets/widget.py", line 693, in notify_change
    self.send_state(key=name)
  File "/Users/adamimos/anaconda3/envs/epsilon-machine/lib/python3.11/site-packages/ipywidgets/widgets/widget.py", line 579, in send_state
    self._send(msg, buffers=buffers)
  File "/Users/adamimos/anaconda3/envs/epsilon-machine/lib/python3.11/site-packages/ipywidgets/widgets/widget.py", line 818, in _send
    self.comm.send(data=msg, buffers=buffers)
  File "/Users/adamimos/anaconda3/envs/epsilon-machine/lib/python3.11/site-packages/comm/base_comm.py", line 113, in send
    self.publish_msg(
  File "/Users/adamimos/anaconda3/envs/epsilon-machine/lib/python3.11/site-packages/ipykernel/comm/comm.py", line 36, in publish_msg
    self.kernel.session.send(
  File "/Users/adamimos/anaconda3/envs/epsilon-machine/lib/python3.11/site-packages/jupyter_client/session.py", line 863, in send
    stream.send_multipart(to_send, copy=copy)
  File "/Users/adamimos/anaconda3/envs/epsilon-machine/lib/python3.11/site-packages/ipykernel/iostream.py", line 330, in send_multipart
    return self.io_thread.send_multipart(*args, **kwargs)
           ^^^^^^^^^^^^^^^^^^^^^^^^^^^^^^^^^^^^^^^^^^^^^^
  File "/Users/adamimos/anaconda3/envs/epsilon-machine/lib/python3.11/site-packages/ipykernel/iostream.py", line 260, in send_multipart
    self.schedule(lambda: self._really_send(*args, **kwargs))
  File "/Users/adamimos/anaconda3/envs/epsilon-machine/lib/python3.11/site-packages/ipykernel/iostream.py", line 251, in schedule
    self._event_pipe.send(b"")
  File "/Users/adamimos/anaconda3/envs/epsilon-machine/lib/python3.11/site-packages/zmq/sugar/socket.py", line 696, in send
    return super().send(data, flags=flags, copy=copy, track=track)
           ^^^^^^^^^^^^^^^^^^^^^^^^^^^^^^^^^^^^^^^^^^^^^^^^^^^^^^^
  File "zmq/backend/cython/socket.pyx", line 742, in zmq.backend.cython.socket.Socket.send
  File "zmq/backend/cython/socket.pyx", line 783, in zmq.backend.cython.socket.Socket.send
  File "zmq/backend/cython/socket.pyx", line 138, in zmq.backend.cython.socket._check_closed
zmq.error.ZMQError: Socket operation on non-socket

During handling of the above exception, another exception occurred:

Traceback (most recent call last):
  File "/Users/adamimos/anaconda3/envs/epsilon-machine/lib/python3.11/site-packages/wandb/sdk/wandb_run.py", line 2211, in _atexit_cleanup
    self._on_finish()
  File "/Users/adamimos/anaconda3/envs/epsilon-machine/lib/python3.11/site-packages/wandb/sdk/wandb_run.py", line 2451, in _on_finish
    _ = exit_handle.wait(timeout=-1, on_progress=self._on_progress_exit)
        ^^^^^^^^^^^^^^^^^^^^^^^^^^^^^^^^^^^^^^^^^^^^^^^^^^^^^^^^^^^^^^^^
  File "/Users/adamimos/anaconda3/envs/epsilon-machine/lib/python3.11/site-packages/wandb/sdk/lib/mailbox.py", line 303, in wait
    on_progress(progress_handle)
  File "/Users/adamimos/anaconda3/envs/epsilon-machine/lib/python3.11/site-packages/wandb/sdk/wandb_run.py", line 2430, in _on_progress_exit
    self._footer_file_pusher_status_info(
  File "/Users/adamimos/anaconda3/envs/epsilon-machine/lib/python3.11/site-packages/wandb/sdk/wandb_run.py", line 3648, in _footer_file_pusher_status_info
    Run._footer_single_run_file_pusher_status_info(
  File "/Users/adamimos/anaconda3/envs/epsilon-machine/lib/python3.11/site-packages/wandb/sdk/wandb_run.py", line 3699, in _footer_single_run_file_pusher_status_info
    printer.progress_update(line, percent_done)
  File "/Users/adamimos/anaconda3/envs/epsilon-machine/lib/python3.11/site-packages/wandb/sdk/lib/printer.py", line 288, in progress_update
    self._progress.update(percent_done, text)
  File "/Users/adamimos/anaconda3/envs/epsilon-machine/lib/python3.11/site-packages/wandb/sdk/lib/ipython.py", line 121, in update
    wandb.termwarn(
  File "/Users/adamimos/anaconda3/envs/epsilon-machine/lib/python3.11/site-packages/wandb/errors/term.py", line 50, in termwarn
    _log(
  File "/Users/adamimos/anaconda3/envs/epsilon-machine/lib/python3.11/site-packages/wandb/errors/term.py", line 95, in _log
    click.echo(line, file=sys.stderr, nl=newline)
  File "/Users/adamimos/anaconda3/envs/epsilon-machine/lib/python3.11/site-packages/click/utils.py", line 319, in echo
    file.flush()
  File "/Users/adamimos/anaconda3/envs/epsilon-machine/lib/python3.11/site-packages/ipykernel/iostream.py", line 559, in flush
    self.pub_thread.schedule(self._flush)
  File "/Users/adamimos/anaconda3/envs/epsilon-machine/lib/python3.11/site-packages/ipykernel/iostream.py", line 251, in schedule
    self._event_pipe.send(b"")
  File "/Users/adamimos/anaconda3/envs/epsilon-machine/lib/python3.11/site-packages/zmq/sugar/socket.py", line 696, in send
    return super().send(data, flags=flags, copy=copy, track=track)
           ^^^^^^^^^^^^^^^^^^^^^^^^^^^^^^^^^^^^^^^^^^^^^^^^^^^^^^^
  File "zmq/backend/cython/socket.pyx", line 742, in zmq.backend.cython.socket.Socket.send
  File "zmq/backend/cython/socket.pyx", line 783, in zmq.backend.cython.socket.Socket.send
  File "zmq/backend/cython/socket.pyx", line 138, in zmq.backend.cython.socket._check_closed
zmq.error.ZMQError: Socket operation on non-socket
2024-01-18 19:49:16,393 INFO    MainThread:56485 [pyagent.py:run():314] Starting sweep agent: entity=None, project=None, count=None
