2024-01-19 17:00:17,354 INFO    Thread-113 (_run_job):76495 [wandb_setup.py:_flush():76] Current SDK version is 0.16.1
2024-01-19 17:00:17,354 INFO    Thread-113 (_run_job):76495 [wandb_setup.py:_flush():76] Configure stats pid to 76495
2024-01-19 17:00:17,354 INFO    Thread-113 (_run_job):76495 [wandb_setup.py:_flush():76] Loading settings from /Users/adamimos/.config/wandb/settings
2024-01-19 17:00:17,354 INFO    Thread-113 (_run_job):76495 [wandb_setup.py:_flush():76] Loading settings from /Users/adamimos/Documents/GitHub/epsilon-transformers/wandb/settings
2024-01-19 17:00:17,355 INFO    Thread-113 (_run_job):76495 [wandb_setup.py:_flush():76] Loading settings from environment variables: {'project': 'epsilon-transformer', 'entity': 'adamimos', 'root_dir': '/Users/adamimos/Documents/GitHub/epsilon-transformers', 'run_id': 'wmy54nnt', 'sweep_param_path': '/Users/adamimos/Documents/GitHub/epsilon-transformers/wandb/sweep-eaedbzxy/config-wmy54nnt.yaml', 'sweep_id': 'eaedbzxy'}
2024-01-19 17:00:17,355 INFO    Thread-113 (_run_job):76495 [wandb_setup.py:_flush():76] Applying setup settings: {'_disable_service': False}
2024-01-19 17:00:17,355 INFO    Thread-113 (_run_job):76495 [wandb_setup.py:_flush():76] Inferring run settings from compute environment: {'program': '<python with no main file>'}
2024-01-19 17:00:17,355 INFO    Thread-113 (_run_job):76495 [wandb_init.py:_log_setup():524] Logging user logs to /Users/adamimos/Documents/GitHub/epsilon-transformers/wandb/run-20240119_170017-wmy54nnt/logs/debug.log
2024-01-19 17:00:17,355 INFO    Thread-113 (_run_job):76495 [wandb_init.py:_log_setup():525] Logging internal logs to /Users/adamimos/Documents/GitHub/epsilon-transformers/wandb/run-20240119_170017-wmy54nnt/logs/debug-internal.log
2024-01-19 17:00:17,355 INFO    Thread-113 (_run_job):76495 [wandb_init.py:_jupyter_setup():470] configuring jupyter hooks <wandb.sdk.wandb_init._WandbInit object at 0x2ba263a50>
2024-01-19 17:00:17,355 INFO    Thread-113 (_run_job):76495 [wandb_init.py:init():564] calling init triggers
2024-01-19 17:00:17,355 INFO    Thread-113 (_run_job):76495 [wandb_init.py:init():571] wandb.init called with sweep_config: {'learning_rate': 0.003593813663804626, 'weight_decay': 0}
config: {}
2024-01-19 17:00:17,355 INFO    Thread-113 (_run_job):76495 [wandb_init.py:init():614] starting backend
2024-01-19 17:00:17,355 INFO    Thread-113 (_run_job):76495 [wandb_init.py:init():618] setting up manager
2024-01-19 17:00:17,360 INFO    Thread-113 (_run_job):76495 [backend.py:_multiprocessing_setup():105] multiprocessing start_methods=spawn,fork,forkserver, using: spawn
2024-01-19 17:00:17,360 INFO    Thread-113 (_run_job):76495 [wandb_init.py:init():624] backend started and connected
2024-01-19 17:00:17,371 INFO    Thread-113 (_run_job):76495 [wandb_run.py:_config_callback():1342] config_cb None None {'learning_rate': 0.003593813663804626, 'weight_decay': 0}
2024-01-19 17:00:17,382 INFO    Thread-113 (_run_job):76495 [wandb_run.py:_label_probe_notebook():1294] probe notebook
2024-01-19 17:00:17,382 INFO    Thread-113 (_run_job):76495 [wandb_run.py:_label_probe_notebook():1304] Unable to probe notebook: 'NoneType' object has no attribute 'get'
2024-01-19 17:00:17,382 INFO    Thread-113 (_run_job):76495 [wandb_init.py:init():716] updated telemetry
2024-01-19 17:00:17,399 INFO    Thread-113 (_run_job):76495 [wandb_init.py:init():749] communicating run to backend with 90.0 second timeout
2024-01-19 17:00:17,647 INFO    Thread-113 (_run_job):76495 [wandb_run.py:_on_init():2254] communicating current version
2024-01-19 17:00:17,720 INFO    Thread-113 (_run_job):76495 [wandb_run.py:_on_init():2263] got version response upgrade_message: "wandb version 0.16.2 is available!  To upgrade, please run:\n $ pip install wandb --upgrade"

2024-01-19 17:00:17,720 INFO    Thread-113 (_run_job):76495 [wandb_init.py:init():800] starting run threads in backend
2024-01-19 17:00:19,117 INFO    Thread-113 (_run_job):76495 [wandb_run.py:_console_start():2233] atexit reg
2024-01-19 17:00:19,117 INFO    Thread-113 (_run_job):76495 [wandb_run.py:_redirect():2088] redirect: wrap_raw
2024-01-19 17:00:19,117 INFO    Thread-113 (_run_job):76495 [wandb_run.py:_redirect():2153] Wrapping output streams.
2024-01-19 17:00:19,117 INFO    Thread-113 (_run_job):76495 [wandb_run.py:_redirect():2178] Redirects installed.
2024-01-19 17:00:19,118 INFO    Thread-113 (_run_job):76495 [wandb_init.py:init():841] run started, returning control to user process
2024-01-19 17:00:19,718 INFO    Thread-113 (_run_job):76495 [wandb_run.py:_config_callback():1342] config_cb None None {'model_config': {'n_layers': 2, 'd_model': 16, 'n_ctx': 10, 'd_head': 4, 'model_name': 'custom', 'n_heads': 4, 'd_mlp': 64, 'act_fn': 'relu', 'd_vocab': 2, 'eps': 1e-05, 'use_attn_result': False, 'use_attn_scale': True, 'use_split_qkv_input': False, 'use_hook_mlp_in': False, 'use_attn_in': False, 'use_local_attn': False, 'original_architecture': None, 'from_checkpoint': False, 'checkpoint_index': None, 'checkpoint_label_type': None, 'checkpoint_value': None, 'tokenizer_name': None, 'window_size': None, 'attn_types': None, 'init_mode': 'gpt2', 'normalization_type': None, 'device': 'cpu', 'n_devices': 1, 'attention_dir': 'causal', 'attn_only': False, 'seed': 42, 'initializer_range': 0.2, 'init_weights': True, 'scale_attn_by_inverse_layer_idx': False, 'positional_embedding_type': 'standard', 'final_rms': False, 'd_vocab_out': 2, 'parallel_attn_mlp': False, 'rotary_dim': None, 'n_params': 6144, 'use_hook_tokens': False, 'gated_mlp': False, 'default_prepend_bos': True, 'dtype': 'torch.float32', 'tokenizer_prepends_bos': None, 'post_embedding_ln': False}, 'train_config': {'batch_size': 64, 'sequence_length': 500, 'num_sequences': 100, 'num_epochs': 200, 'learning_rate': 0.00015, 'weight_decay': 0}}
2024-01-19 17:19:00,266 INFO    Thread-91 (_heartbeat):76495 [retry.py:__call__():172] Retry attempt failed:
Traceback (most recent call last):
  File "/Users/adamimos/anaconda3/envs/epsilon-machine/lib/python3.11/site-packages/urllib3/connection.py", line 174, in _new_conn
    conn = connection.create_connection(
           ^^^^^^^^^^^^^^^^^^^^^^^^^^^^^
  File "/Users/adamimos/anaconda3/envs/epsilon-machine/lib/python3.11/site-packages/urllib3/util/connection.py", line 72, in create_connection
    for res in socket.getaddrinfo(host, port, family, socket.SOCK_STREAM):
               ^^^^^^^^^^^^^^^^^^^^^^^^^^^^^^^^^^^^^^^^^^^^^^^^^^^^^^^^^^
  File "/Users/adamimos/anaconda3/envs/epsilon-machine/lib/python3.11/socket.py", line 962, in getaddrinfo
    for res in _socket.getaddrinfo(host, port, family, type, proto, flags):
               ^^^^^^^^^^^^^^^^^^^^^^^^^^^^^^^^^^^^^^^^^^^^^^^^^^^^^^^^^^^
socket.gaierror: [Errno 8] nodename nor servname provided, or not known

During handling of the above exception, another exception occurred:

Traceback (most recent call last):
  File "/Users/adamimos/anaconda3/envs/epsilon-machine/lib/python3.11/site-packages/urllib3/connectionpool.py", line 715, in urlopen
    httplib_response = self._make_request(
                       ^^^^^^^^^^^^^^^^^^^
  File "/Users/adamimos/anaconda3/envs/epsilon-machine/lib/python3.11/site-packages/urllib3/connectionpool.py", line 404, in _make_request
    self._validate_conn(conn)
  File "/Users/adamimos/anaconda3/envs/epsilon-machine/lib/python3.11/site-packages/urllib3/connectionpool.py", line 1058, in _validate_conn
    conn.connect()
  File "/Users/adamimos/anaconda3/envs/epsilon-machine/lib/python3.11/site-packages/urllib3/connection.py", line 363, in connect
    self.sock = conn = self._new_conn()
                       ^^^^^^^^^^^^^^^^
  File "/Users/adamimos/anaconda3/envs/epsilon-machine/lib/python3.11/site-packages/urllib3/connection.py", line 186, in _new_conn
    raise NewConnectionError(
urllib3.exceptions.NewConnectionError: <urllib3.connection.HTTPSConnection object at 0x2ba308bd0>: Failed to establish a new connection: [Errno 8] nodename nor servname provided, or not known

During handling of the above exception, another exception occurred:

Traceback (most recent call last):
  File "/Users/adamimos/anaconda3/envs/epsilon-machine/lib/python3.11/site-packages/requests/adapters.py", line 486, in send
    resp = conn.urlopen(
           ^^^^^^^^^^^^^
  File "/Users/adamimos/anaconda3/envs/epsilon-machine/lib/python3.11/site-packages/urllib3/connectionpool.py", line 799, in urlopen
    retries = retries.increment(
              ^^^^^^^^^^^^^^^^^^
  File "/Users/adamimos/anaconda3/envs/epsilon-machine/lib/python3.11/site-packages/urllib3/util/retry.py", line 592, in increment
    raise MaxRetryError(_pool, url, error or ResponseError(cause))
urllib3.exceptions.MaxRetryError: HTTPSConnectionPool(host='api.wandb.ai', port=443): Max retries exceeded with url: /graphql (Caused by NewConnectionError('<urllib3.connection.HTTPSConnection object at 0x2ba308bd0>: Failed to establish a new connection: [Errno 8] nodename nor servname provided, or not known'))

During handling of the above exception, another exception occurred:

Traceback (most recent call last):
  File "/Users/adamimos/anaconda3/envs/epsilon-machine/lib/python3.11/site-packages/wandb/sdk/lib/retry.py", line 131, in __call__
    result = self._call_fn(*args, **kwargs)
             ^^^^^^^^^^^^^^^^^^^^^^^^^^^^^^
  File "/Users/adamimos/anaconda3/envs/epsilon-machine/lib/python3.11/site-packages/wandb/sdk/internal/internal_api.py", line 369, in execute
    return self.client.execute(*args, **kwargs)  # type: ignore
           ^^^^^^^^^^^^^^^^^^^^^^^^^^^^^^^^^^^^
  File "/Users/adamimos/anaconda3/envs/epsilon-machine/lib/python3.11/site-packages/wandb/vendor/gql-0.2.0/wandb_gql/client.py", line 52, in execute
    result = self._get_result(document, *args, **kwargs)
             ^^^^^^^^^^^^^^^^^^^^^^^^^^^^^^^^^^^^^^^^^^^
  File "/Users/adamimos/anaconda3/envs/epsilon-machine/lib/python3.11/site-packages/wandb/vendor/gql-0.2.0/wandb_gql/client.py", line 60, in _get_result
    return self.transport.execute(document, *args, **kwargs)
           ^^^^^^^^^^^^^^^^^^^^^^^^^^^^^^^^^^^^^^^^^^^^^^^^^
  File "/Users/adamimos/anaconda3/envs/epsilon-machine/lib/python3.11/site-packages/wandb/sdk/lib/gql_request.py", line 58, in execute
    request = self.session.post(self.url, **post_args)
              ^^^^^^^^^^^^^^^^^^^^^^^^^^^^^^^^^^^^^^^^
  File "/Users/adamimos/anaconda3/envs/epsilon-machine/lib/python3.11/site-packages/requests/sessions.py", line 637, in post
    return self.request("POST", url, data=data, json=json, **kwargs)
           ^^^^^^^^^^^^^^^^^^^^^^^^^^^^^^^^^^^^^^^^^^^^^^^^^^^^^^^^^
  File "/Users/adamimos/anaconda3/envs/epsilon-machine/lib/python3.11/site-packages/requests/sessions.py", line 589, in request
    resp = self.send(prep, **send_kwargs)
           ^^^^^^^^^^^^^^^^^^^^^^^^^^^^^^
  File "/Users/adamimos/anaconda3/envs/epsilon-machine/lib/python3.11/site-packages/requests/sessions.py", line 703, in send
    r = adapter.send(request, **kwargs)
        ^^^^^^^^^^^^^^^^^^^^^^^^^^^^^^^
  File "/Users/adamimos/anaconda3/envs/epsilon-machine/lib/python3.11/site-packages/requests/adapters.py", line 519, in send
    raise ConnectionError(e, request=request)
requests.exceptions.ConnectionError: HTTPSConnectionPool(host='api.wandb.ai', port=443): Max retries exceeded with url: /graphql (Caused by NewConnectionError('<urllib3.connection.HTTPSConnection object at 0x2ba308bd0>: Failed to establish a new connection: [Errno 8] nodename nor servname provided, or not known'))
2024-01-19 17:25:11,541 INFO    Thread-113 (_run_job):76495 [wandb_run.py:_finish():1962] finishing run adamimos/epsilon-transformer/wmy54nnt
2024-01-19 17:25:11,542 INFO    Thread-113 (_run_job):76495 [jupyter.py:save_history():445] not saving jupyter history
2024-01-19 17:25:11,542 INFO    Thread-113 (_run_job):76495 [jupyter.py:save_ipynb():373] not saving jupyter notebook
2024-01-19 17:25:11,542 INFO    Thread-113 (_run_job):76495 [wandb_init.py:_jupyter_teardown():452] cleaning up jupyter logic
2024-01-19 17:25:11,542 INFO    Thread-113 (_run_job):76495 [wandb_run.py:_atexit_cleanup():2202] got exitcode: 0
2024-01-19 17:25:11,542 INFO    Thread-113 (_run_job):76495 [wandb_run.py:_restore():2185] restore
2024-01-19 17:25:11,542 INFO    Thread-113 (_run_job):76495 [wandb_run.py:_restore():2191] restore done
2024-01-19 21:18:48,448 INFO    Thread-113 (_run_job):76495 [wandb_run.py:_footer_history_summary_info():3837] rendering history
2024-01-19 21:18:48,450 INFO    Thread-113 (_run_job):76495 [wandb_run.py:_footer_history_summary_info():3869] rendering summary
2024-01-19 21:18:48,463 INFO    Thread-113 (_run_job):76495 [wandb_run.py:_footer_sync_info():3796] logging synced files
