
4096
Traceback (most recent call last):
  File "/Users/adamimos/anaconda3/envs/epsilon-machine/lib/python3.11/site-packages/wandb/sdk/wandb_config.py", line 162, in __getattr__
    return self.__getitem__(key)
           ^^^^^^^^^^^^^^^^^^^^^
  File "/Users/adamimos/anaconda3/envs/epsilon-machine/lib/python3.11/site-packages/wandb/sdk/wandb_config.py", line 130, in __getitem__
    return self._items[key]
           ~~~~~~~~~~~^^^^^
KeyError: 'epochs'
The above exception was the direct cause of the following exception:
Traceback (most recent call last):
  File "/Users/adamimos/Documents/GitHub/epsilon-transformers/./test.py", line 53, in sweep_train
    for epoch in range(config.epochs):
                       ^^^^^^^^^^^^^
  File "/Users/adamimos/anaconda3/envs/epsilon-machine/lib/python3.11/site-packages/wandb/sdk/wandb_config.py", line 164, in __getattr__
    raise AttributeError(
AttributeError: <class 'wandb.sdk.wandb_config.Config'> object has no attribute 'epochs'