2024-01-30 09:46:38,373 INFO    Thread-78 (_run_job):95609 [wandb_setup.py:_flush():76] Current SDK version is 0.16.2
2024-01-30 09:46:38,374 INFO    Thread-78 (_run_job):95609 [wandb_setup.py:_flush():76] Configure stats pid to 95609
2024-01-30 09:46:38,374 INFO    Thread-78 (_run_job):95609 [wandb_setup.py:_flush():76] Loading settings from /Users/adamimos/.config/wandb/settings
2024-01-30 09:46:38,374 INFO    Thread-78 (_run_job):95609 [wandb_setup.py:_flush():76] Loading settings from /Users/adamimos/Documents/GitHub/epsilon-transformers/wandb/settings
2024-01-30 09:46:38,374 INFO    Thread-78 (_run_job):95609 [wandb_setup.py:_flush():76] Loading settings from environment variables: {'project': 'RRXOR_initial_sweep', 'entity': 'adamimos', 'root_dir': '/Users/adamimos/Documents/GitHub/epsilon-transformers', 'run_id': 'hqgvso5m', 'sweep_param_path': '/Users/adamimos/Documents/GitHub/epsilon-transformers/wandb/sweep-01wbsqrn/config-hqgvso5m.yaml', 'sweep_id': '01wbsqrn'}
2024-01-30 09:46:38,374 INFO    Thread-78 (_run_job):95609 [wandb_setup.py:_flush():76] Applying setup settings: {'_disable_service': False}
2024-01-30 09:46:38,374 INFO    Thread-78 (_run_job):95609 [wandb_setup.py:_flush():76] Inferring run settings from compute environment: {'program_relpath': 'test.py', 'program_abspath': '/Users/adamimos/Documents/GitHub/epsilon-transformers/test.py', 'program': '/Users/adamimos/Documents/GitHub/epsilon-transformers/./test.py'}
2024-01-30 09:46:38,374 INFO    Thread-78 (_run_job):95609 [wandb_init.py:_log_setup():526] Logging user logs to /Users/adamimos/Documents/GitHub/epsilon-transformers/wandb/run-20240130_094638-hqgvso5m/logs/debug.log
2024-01-30 09:46:38,374 INFO    Thread-78 (_run_job):95609 [wandb_init.py:_log_setup():527] Logging internal logs to /Users/adamimos/Documents/GitHub/epsilon-transformers/wandb/run-20240130_094638-hqgvso5m/logs/debug-internal.log
2024-01-30 09:46:38,374 INFO    Thread-78 (_run_job):95609 [wandb_init.py:init():566] calling init triggers
2024-01-30 09:46:38,374 INFO    Thread-78 (_run_job):95609 [wandb_init.py:init():573] wandb.init called with sweep_config: {'act_fn': 'relu', 'attention_dir': 'causal', 'attn_only': False, 'batch_size': 8192, 'd_head': 8, 'd_mlp': 256, 'd_model': 256, 'd_vocab': 2, 'init_weights': True, 'learning_rate': 0.1, 'n_ctx': 10, 'n_heads': 2, 'n_layers': 8, 'normalization_type': 'LN', 'num_epochs': 10000, 'optimizer': 'adam', 'seed': 42, 'use_attn_scale': True, 'weight_decay': 0.01}
config: {}
2024-01-30 09:46:38,375 INFO    Thread-78 (_run_job):95609 [wandb_init.py:init():616] starting backend
2024-01-30 09:46:38,375 INFO    Thread-78 (_run_job):95609 [wandb_init.py:init():620] setting up manager
2024-01-30 09:46:38,381 INFO    Thread-78 (_run_job):95609 [backend.py:_multiprocessing_setup():105] multiprocessing start_methods=spawn,fork,forkserver, using: spawn
2024-01-30 09:46:38,381 INFO    Thread-78 (_run_job):95609 [wandb_init.py:init():628] backend started and connected
2024-01-30 09:46:38,390 INFO    Thread-78 (_run_job):95609 [wandb_run.py:_config_callback():1342] config_cb None None {'act_fn': 'relu', 'attention_dir': 'causal', 'attn_only': False, 'batch_size': 8192, 'd_head': 8, 'd_mlp': 256, 'd_model': 256, 'd_vocab': 2, 'init_weights': True, 'learning_rate': 0.1, 'n_ctx': 10, 'n_heads': 2, 'n_layers': 8, 'normalization_type': 'LN', 'num_epochs': 10000, 'optimizer': 'adam', 'seed': 42, 'use_attn_scale': True, 'weight_decay': 0.01}
2024-01-30 09:46:38,396 INFO    Thread-78 (_run_job):95609 [wandb_init.py:init():720] updated telemetry
2024-01-30 09:46:38,468 INFO    Thread-78 (_run_job):95609 [wandb_init.py:init():753] communicating run to backend with 90.0 second timeout
2024-01-30 09:46:38,716 INFO    Thread-78 (_run_job):95609 [wandb_run.py:_on_init():2254] communicating current version
2024-01-30 09:46:43,725 INFO    Thread-78 (_run_job):95609 [wandb_run.py:_on_init():2263] got version response 
2024-01-30 09:46:43,725 INFO    Thread-78 (_run_job):95609 [wandb_init.py:init():804] starting run threads in backend
2024-01-30 09:46:46,707 INFO    Thread-78 (_run_job):95609 [wandb_run.py:_console_start():2233] atexit reg
2024-01-30 09:46:46,707 INFO    Thread-78 (_run_job):95609 [wandb_run.py:_redirect():2088] redirect: wrap_raw
2024-01-30 09:46:46,707 INFO    Thread-78 (_run_job):95609 [wandb_run.py:_redirect():2153] Wrapping output streams.
2024-01-30 09:46:46,708 INFO    Thread-78 (_run_job):95609 [wandb_run.py:_redirect():2178] Redirects installed.
2024-01-30 09:46:46,708 INFO    Thread-78 (_run_job):95609 [wandb_init.py:init():847] run started, returning control to user process
2024-01-30 09:50:27,614 ERROR   Thread-1 (_heartbeat):95609 [internal_api.py:execute():373] 500 response executing GraphQL.
2024-01-30 09:50:27,615 ERROR   Thread-1 (_heartbeat):95609 [internal_api.py:execute():374] {"errors":[{"message":"context deadline exceeded"}]}
2024-01-30 09:51:23,862 ERROR   Thread-1 (_heartbeat):95609 [internal_api.py:execute():373] 500 response executing GraphQL.
2024-01-30 09:51:23,862 ERROR   Thread-1 (_heartbeat):95609 [internal_api.py:execute():374] {"errors":[{"message":"context deadline exceeded"}]}
2024-01-30 09:52:57,348 ERROR   Thread-1 (_heartbeat):95609 [internal_api.py:execute():373] 500 response executing GraphQL.
2024-01-30 09:52:57,349 ERROR   Thread-1 (_heartbeat):95609 [internal_api.py:execute():374] {"errors":[{"message":"context deadline exceeded"}]}
2024-01-30 09:55:58,094 ERROR   Thread-1 (_heartbeat):95609 [internal_api.py:execute():373] 500 response executing GraphQL.
2024-01-30 09:55:58,094 ERROR   Thread-1 (_heartbeat):95609 [internal_api.py:execute():374] {"errors":[{"message":"context deadline exceeded"}]}
2024-01-30 09:59:52,786 ERROR   Thread-1 (_heartbeat):95609 [internal_api.py:execute():373] 500 response executing GraphQL.
2024-01-30 09:59:52,786 ERROR   Thread-1 (_heartbeat):95609 [internal_api.py:execute():374] {"errors":[{"message":"context deadline exceeded"}]}
2024-01-30 10:00:49,035 ERROR   Thread-1 (_heartbeat):95609 [internal_api.py:execute():373] 500 response executing GraphQL.
2024-01-30 10:00:49,036 ERROR   Thread-1 (_heartbeat):95609 [internal_api.py:execute():374] {"error":"context deadline exceeded"}
2024-01-30 10:01:51,403 INFO    Thread-1 (_heartbeat):95609 [retry.py:__call__():172] Retry attempt failed:
Traceback (most recent call last):
  File "/Users/adamimos/anaconda3/envs/epsilon-machine/lib/python3.11/site-packages/urllib3/connectionpool.py", line 467, in _make_request
    six.raise_from(e, None)
  File "<string>", line 3, in raise_from
  File "/Users/adamimos/anaconda3/envs/epsilon-machine/lib/python3.11/site-packages/urllib3/connectionpool.py", line 462, in _make_request
    httplib_response = conn.getresponse()
                       ^^^^^^^^^^^^^^^^^^
  File "/Users/adamimos/anaconda3/envs/epsilon-machine/lib/python3.11/http/client.py", line 1386, in getresponse
    response.begin()
  File "/Users/adamimos/anaconda3/envs/epsilon-machine/lib/python3.11/http/client.py", line 325, in begin
    version, status, reason = self._read_status()
                              ^^^^^^^^^^^^^^^^^^^
  File "/Users/adamimos/anaconda3/envs/epsilon-machine/lib/python3.11/http/client.py", line 286, in _read_status
    line = str(self.fp.readline(_MAXLINE + 1), "iso-8859-1")
               ^^^^^^^^^^^^^^^^^^^^^^^^^^^^^^
  File "/Users/adamimos/anaconda3/envs/epsilon-machine/lib/python3.11/socket.py", line 706, in readinto
    return self._sock.recv_into(b)
           ^^^^^^^^^^^^^^^^^^^^^^^
  File "/Users/adamimos/anaconda3/envs/epsilon-machine/lib/python3.11/ssl.py", line 1315, in recv_into
    return self.read(nbytes, buffer)
           ^^^^^^^^^^^^^^^^^^^^^^^^^
  File "/Users/adamimos/anaconda3/envs/epsilon-machine/lib/python3.11/ssl.py", line 1167, in read
    return self._sslobj.read(len, buffer)
           ^^^^^^^^^^^^^^^^^^^^^^^^^^^^^^
TimeoutError: The read operation timed out

During handling of the above exception, another exception occurred:

Traceback (most recent call last):
  File "/Users/adamimos/anaconda3/envs/epsilon-machine/lib/python3.11/site-packages/requests/adapters.py", line 486, in send
    resp = conn.urlopen(
           ^^^^^^^^^^^^^
  File "/Users/adamimos/anaconda3/envs/epsilon-machine/lib/python3.11/site-packages/urllib3/connectionpool.py", line 799, in urlopen
    retries = retries.increment(
              ^^^^^^^^^^^^^^^^^^
  File "/Users/adamimos/anaconda3/envs/epsilon-machine/lib/python3.11/site-packages/urllib3/util/retry.py", line 550, in increment
    raise six.reraise(type(error), error, _stacktrace)
          ^^^^^^^^^^^^^^^^^^^^^^^^^^^^^^^^^^^^^^^^^^^^
  File "/Users/adamimos/anaconda3/envs/epsilon-machine/lib/python3.11/site-packages/urllib3/packages/six.py", line 770, in reraise
    raise value
  File "/Users/adamimos/anaconda3/envs/epsilon-machine/lib/python3.11/site-packages/urllib3/connectionpool.py", line 715, in urlopen
    httplib_response = self._make_request(
                       ^^^^^^^^^^^^^^^^^^^
  File "/Users/adamimos/anaconda3/envs/epsilon-machine/lib/python3.11/site-packages/urllib3/connectionpool.py", line 469, in _make_request
    self._raise_timeout(err=e, url=url, timeout_value=read_timeout)
  File "/Users/adamimos/anaconda3/envs/epsilon-machine/lib/python3.11/site-packages/urllib3/connectionpool.py", line 358, in _raise_timeout
    raise ReadTimeoutError(
urllib3.exceptions.ReadTimeoutError: HTTPSConnectionPool(host='api.wandb.ai', port=443): Read timed out. (read timeout=60)

During handling of the above exception, another exception occurred:

Traceback (most recent call last):
  File "/Users/adamimos/anaconda3/envs/epsilon-machine/lib/python3.11/site-packages/wandb/sdk/lib/retry.py", line 131, in __call__
    result = self._call_fn(*args, **kwargs)
             ^^^^^^^^^^^^^^^^^^^^^^^^^^^^^^
  File "/Users/adamimos/anaconda3/envs/epsilon-machine/lib/python3.11/site-packages/wandb/sdk/internal/internal_api.py", line 369, in execute
    return self.client.execute(*args, **kwargs)  # type: ignore
           ^^^^^^^^^^^^^^^^^^^^^^^^^^^^^^^^^^^^
  File "/Users/adamimos/anaconda3/envs/epsilon-machine/lib/python3.11/site-packages/wandb/vendor/gql-0.2.0/wandb_gql/client.py", line 52, in execute
    result = self._get_result(document, *args, **kwargs)
             ^^^^^^^^^^^^^^^^^^^^^^^^^^^^^^^^^^^^^^^^^^^
  File "/Users/adamimos/anaconda3/envs/epsilon-machine/lib/python3.11/site-packages/wandb/vendor/gql-0.2.0/wandb_gql/client.py", line 60, in _get_result
    return self.transport.execute(document, *args, **kwargs)
           ^^^^^^^^^^^^^^^^^^^^^^^^^^^^^^^^^^^^^^^^^^^^^^^^^
  File "/Users/adamimos/anaconda3/envs/epsilon-machine/lib/python3.11/site-packages/wandb/sdk/lib/gql_request.py", line 58, in execute
    request = self.session.post(self.url, **post_args)
              ^^^^^^^^^^^^^^^^^^^^^^^^^^^^^^^^^^^^^^^^
  File "/Users/adamimos/anaconda3/envs/epsilon-machine/lib/python3.11/site-packages/requests/sessions.py", line 637, in post
    return self.request("POST", url, data=data, json=json, **kwargs)
           ^^^^^^^^^^^^^^^^^^^^^^^^^^^^^^^^^^^^^^^^^^^^^^^^^^^^^^^^^
  File "/Users/adamimos/anaconda3/envs/epsilon-machine/lib/python3.11/site-packages/requests/sessions.py", line 589, in request
    resp = self.send(prep, **send_kwargs)
           ^^^^^^^^^^^^^^^^^^^^^^^^^^^^^^
  File "/Users/adamimos/anaconda3/envs/epsilon-machine/lib/python3.11/site-packages/requests/sessions.py", line 703, in send
    r = adapter.send(request, **kwargs)
        ^^^^^^^^^^^^^^^^^^^^^^^^^^^^^^^
  File "/Users/adamimos/anaconda3/envs/epsilon-machine/lib/python3.11/site-packages/requests/adapters.py", line 532, in send
    raise ReadTimeout(e, request=request)
requests.exceptions.ReadTimeout: HTTPSConnectionPool(host='api.wandb.ai', port=443): Read timed out. (read timeout=60)
2024-01-30 10:14:02,672 INFO    Thread-78 (_run_job):95609 [wandb_run.py:_finish():1962] finishing run adamimos/RRXOR_initial_sweep/hqgvso5m
2024-01-30 10:14:02,674 INFO    Thread-78 (_run_job):95609 [wandb_run.py:_atexit_cleanup():2202] got exitcode: 0
2024-01-30 10:14:02,677 INFO    Thread-78 (_run_job):95609 [wandb_run.py:_restore():2185] restore
2024-01-30 10:14:02,681 INFO    Thread-78 (_run_job):95609 [wandb_run.py:_restore():2191] restore done
2024-01-30 10:14:13,047 INFO    Thread-78 (_run_job):95609 [wandb_run.py:_footer_history_summary_info():3857] rendering history
2024-01-30 10:14:13,049 INFO    Thread-78 (_run_job):95609 [wandb_run.py:_footer_history_summary_info():3889] rendering summary
2024-01-30 10:14:13,070 INFO    Thread-78 (_run_job):95609 [wandb_run.py:_footer_sync_info():3816] logging synced files
