2024-01-30 08:36:31,767 INFO    Thread-69 (_run_job):95609 [wandb_setup.py:_flush():76] Current SDK version is 0.16.2
2024-01-30 08:36:31,768 INFO    Thread-69 (_run_job):95609 [wandb_setup.py:_flush():76] Configure stats pid to 95609
2024-01-30 08:36:31,768 INFO    Thread-69 (_run_job):95609 [wandb_setup.py:_flush():76] Loading settings from /Users/adamimos/.config/wandb/settings
2024-01-30 08:36:31,768 INFO    Thread-69 (_run_job):95609 [wandb_setup.py:_flush():76] Loading settings from /Users/adamimos/Documents/GitHub/epsilon-transformers/wandb/settings
2024-01-30 08:36:31,768 INFO    Thread-69 (_run_job):95609 [wandb_setup.py:_flush():76] Loading settings from environment variables: {'project': 'RRXOR_initial_sweep', 'entity': 'adamimos', 'root_dir': '/Users/adamimos/Documents/GitHub/epsilon-transformers', 'run_id': 'f01p000v', 'sweep_param_path': '/Users/adamimos/Documents/GitHub/epsilon-transformers/wandb/sweep-01wbsqrn/config-f01p000v.yaml', 'sweep_id': '01wbsqrn'}
2024-01-30 08:36:31,768 INFO    Thread-69 (_run_job):95609 [wandb_setup.py:_flush():76] Applying setup settings: {'_disable_service': False}
2024-01-30 08:36:31,768 INFO    Thread-69 (_run_job):95609 [wandb_setup.py:_flush():76] Inferring run settings from compute environment: {'program_relpath': 'test.py', 'program_abspath': '/Users/adamimos/Documents/GitHub/epsilon-transformers/test.py', 'program': '/Users/adamimos/Documents/GitHub/epsilon-transformers/./test.py'}
2024-01-30 08:36:31,768 INFO    Thread-69 (_run_job):95609 [wandb_init.py:_log_setup():526] Logging user logs to /Users/adamimos/Documents/GitHub/epsilon-transformers/wandb/run-20240130_083631-f01p000v/logs/debug.log
2024-01-30 08:36:31,769 INFO    Thread-69 (_run_job):95609 [wandb_init.py:_log_setup():527] Logging internal logs to /Users/adamimos/Documents/GitHub/epsilon-transformers/wandb/run-20240130_083631-f01p000v/logs/debug-internal.log
2024-01-30 08:36:31,769 INFO    Thread-69 (_run_job):95609 [wandb_init.py:init():566] calling init triggers
2024-01-30 08:36:31,769 INFO    Thread-69 (_run_job):95609 [wandb_init.py:init():573] wandb.init called with sweep_config: {'act_fn': 'relu', 'attention_dir': 'causal', 'attn_only': False, 'batch_size': 8192, 'd_head': 8, 'd_mlp': 32, 'd_model': 128, 'd_vocab': 2, 'init_weights': True, 'learning_rate': 0.0001, 'n_ctx': 10, 'n_heads': 2, 'n_layers': 4, 'normalization_type': 'LN', 'num_epochs': 10000, 'optimizer': 'adam', 'seed': 42, 'use_attn_scale': True, 'weight_decay': 0}
config: {}
2024-01-30 08:36:31,769 INFO    Thread-69 (_run_job):95609 [wandb_init.py:init():616] starting backend
2024-01-30 08:36:31,769 INFO    Thread-69 (_run_job):95609 [wandb_init.py:init():620] setting up manager
2024-01-30 08:36:31,777 INFO    Thread-69 (_run_job):95609 [backend.py:_multiprocessing_setup():105] multiprocessing start_methods=spawn,fork,forkserver, using: spawn
2024-01-30 08:36:31,778 INFO    Thread-69 (_run_job):95609 [wandb_init.py:init():628] backend started and connected
2024-01-30 08:36:31,786 INFO    Thread-69 (_run_job):95609 [wandb_run.py:_config_callback():1342] config_cb None None {'act_fn': 'relu', 'attention_dir': 'causal', 'attn_only': False, 'batch_size': 8192, 'd_head': 8, 'd_mlp': 32, 'd_model': 128, 'd_vocab': 2, 'init_weights': True, 'learning_rate': 0.0001, 'n_ctx': 10, 'n_heads': 2, 'n_layers': 4, 'normalization_type': 'LN', 'num_epochs': 10000, 'optimizer': 'adam', 'seed': 42, 'use_attn_scale': True, 'weight_decay': 0}
2024-01-30 08:36:31,796 INFO    Thread-69 (_run_job):95609 [wandb_init.py:init():720] updated telemetry
2024-01-30 08:36:31,918 INFO    Thread-69 (_run_job):95609 [wandb_init.py:init():753] communicating run to backend with 90.0 second timeout
2024-01-30 08:36:32,287 INFO    Thread-69 (_run_job):95609 [wandb_run.py:_on_init():2254] communicating current version
2024-01-30 08:36:32,359 INFO    Thread-69 (_run_job):95609 [wandb_run.py:_on_init():2263] got version response 
2024-01-30 08:36:32,359 INFO    Thread-69 (_run_job):95609 [wandb_init.py:init():804] starting run threads in backend
2024-01-30 08:36:33,895 INFO    Thread-69 (_run_job):95609 [wandb_run.py:_console_start():2233] atexit reg
2024-01-30 08:36:33,895 INFO    Thread-69 (_run_job):95609 [wandb_run.py:_redirect():2088] redirect: wrap_raw
2024-01-30 08:36:33,895 INFO    Thread-69 (_run_job):95609 [wandb_run.py:_redirect():2153] Wrapping output streams.
2024-01-30 08:36:33,896 INFO    Thread-69 (_run_job):95609 [wandb_run.py:_redirect():2178] Redirects installed.
2024-01-30 08:36:33,896 INFO    Thread-69 (_run_job):95609 [wandb_init.py:init():847] run started, returning control to user process
2024-01-30 08:42:07,056 INFO    Thread-1 (_heartbeat):95609 [retry.py:__call__():172] Retry attempt failed:
Traceback (most recent call last):
  File "/Users/adamimos/anaconda3/envs/epsilon-machine/lib/python3.11/site-packages/urllib3/connection.py", line 174, in _new_conn
    conn = connection.create_connection(
           ^^^^^^^^^^^^^^^^^^^^^^^^^^^^^
  File "/Users/adamimos/anaconda3/envs/epsilon-machine/lib/python3.11/site-packages/urllib3/util/connection.py", line 72, in create_connection
    for res in socket.getaddrinfo(host, port, family, socket.SOCK_STREAM):
               ^^^^^^^^^^^^^^^^^^^^^^^^^^^^^^^^^^^^^^^^^^^^^^^^^^^^^^^^^^
  File "/Users/adamimos/anaconda3/envs/epsilon-machine/lib/python3.11/socket.py", line 962, in getaddrinfo
    for res in _socket.getaddrinfo(host, port, family, type, proto, flags):
               ^^^^^^^^^^^^^^^^^^^^^^^^^^^^^^^^^^^^^^^^^^^^^^^^^^^^^^^^^^^
socket.gaierror: [Errno 8] nodename nor servname provided, or not known

During handling of the above exception, another exception occurred:

Traceback (most recent call last):
  File "/Users/adamimos/anaconda3/envs/epsilon-machine/lib/python3.11/site-packages/urllib3/connectionpool.py", line 715, in urlopen
    httplib_response = self._make_request(
                       ^^^^^^^^^^^^^^^^^^^
  File "/Users/adamimos/anaconda3/envs/epsilon-machine/lib/python3.11/site-packages/urllib3/connectionpool.py", line 404, in _make_request
    self._validate_conn(conn)
  File "/Users/adamimos/anaconda3/envs/epsilon-machine/lib/python3.11/site-packages/urllib3/connectionpool.py", line 1058, in _validate_conn
    conn.connect()
  File "/Users/adamimos/anaconda3/envs/epsilon-machine/lib/python3.11/site-packages/urllib3/connection.py", line 363, in connect
    self.sock = conn = self._new_conn()
                       ^^^^^^^^^^^^^^^^
  File "/Users/adamimos/anaconda3/envs/epsilon-machine/lib/python3.11/site-packages/urllib3/connection.py", line 186, in _new_conn
    raise NewConnectionError(
urllib3.exceptions.NewConnectionError: <urllib3.connection.HTTPSConnection object at 0x2bd765ed0>: Failed to establish a new connection: [Errno 8] nodename nor servname provided, or not known

During handling of the above exception, another exception occurred:

Traceback (most recent call last):
  File "/Users/adamimos/anaconda3/envs/epsilon-machine/lib/python3.11/site-packages/requests/adapters.py", line 486, in send
    resp = conn.urlopen(
           ^^^^^^^^^^^^^
  File "/Users/adamimos/anaconda3/envs/epsilon-machine/lib/python3.11/site-packages/urllib3/connectionpool.py", line 799, in urlopen
    retries = retries.increment(
              ^^^^^^^^^^^^^^^^^^
  File "/Users/adamimos/anaconda3/envs/epsilon-machine/lib/python3.11/site-packages/urllib3/util/retry.py", line 592, in increment
    raise MaxRetryError(_pool, url, error or ResponseError(cause))
urllib3.exceptions.MaxRetryError: HTTPSConnectionPool(host='api.wandb.ai', port=443): Max retries exceeded with url: /graphql (Caused by NewConnectionError('<urllib3.connection.HTTPSConnection object at 0x2bd765ed0>: Failed to establish a new connection: [Errno 8] nodename nor servname provided, or not known'))

During handling of the above exception, another exception occurred:

Traceback (most recent call last):
  File "/Users/adamimos/anaconda3/envs/epsilon-machine/lib/python3.11/site-packages/wandb/sdk/lib/retry.py", line 131, in __call__
    result = self._call_fn(*args, **kwargs)
             ^^^^^^^^^^^^^^^^^^^^^^^^^^^^^^
  File "/Users/adamimos/anaconda3/envs/epsilon-machine/lib/python3.11/site-packages/wandb/sdk/internal/internal_api.py", line 369, in execute
    return self.client.execute(*args, **kwargs)  # type: ignore
           ^^^^^^^^^^^^^^^^^^^^^^^^^^^^^^^^^^^^
  File "/Users/adamimos/anaconda3/envs/epsilon-machine/lib/python3.11/site-packages/wandb/vendor/gql-0.2.0/wandb_gql/client.py", line 52, in execute
    result = self._get_result(document, *args, **kwargs)
             ^^^^^^^^^^^^^^^^^^^^^^^^^^^^^^^^^^^^^^^^^^^
  File "/Users/adamimos/anaconda3/envs/epsilon-machine/lib/python3.11/site-packages/wandb/vendor/gql-0.2.0/wandb_gql/client.py", line 60, in _get_result
    return self.transport.execute(document, *args, **kwargs)
           ^^^^^^^^^^^^^^^^^^^^^^^^^^^^^^^^^^^^^^^^^^^^^^^^^
  File "/Users/adamimos/anaconda3/envs/epsilon-machine/lib/python3.11/site-packages/wandb/sdk/lib/gql_request.py", line 58, in execute
    request = self.session.post(self.url, **post_args)
              ^^^^^^^^^^^^^^^^^^^^^^^^^^^^^^^^^^^^^^^^
  File "/Users/adamimos/anaconda3/envs/epsilon-machine/lib/python3.11/site-packages/requests/sessions.py", line 637, in post
    return self.request("POST", url, data=data, json=json, **kwargs)
           ^^^^^^^^^^^^^^^^^^^^^^^^^^^^^^^^^^^^^^^^^^^^^^^^^^^^^^^^^
  File "/Users/adamimos/anaconda3/envs/epsilon-machine/lib/python3.11/site-packages/requests/sessions.py", line 589, in request
    resp = self.send(prep, **send_kwargs)
           ^^^^^^^^^^^^^^^^^^^^^^^^^^^^^^
  File "/Users/adamimos/anaconda3/envs/epsilon-machine/lib/python3.11/site-packages/requests/sessions.py", line 703, in send
    r = adapter.send(request, **kwargs)
        ^^^^^^^^^^^^^^^^^^^^^^^^^^^^^^^
  File "/Users/adamimos/anaconda3/envs/epsilon-machine/lib/python3.11/site-packages/requests/adapters.py", line 519, in send
    raise ConnectionError(e, request=request)
requests.exceptions.ConnectionError: HTTPSConnectionPool(host='api.wandb.ai', port=443): Max retries exceeded with url: /graphql (Caused by NewConnectionError('<urllib3.connection.HTTPSConnection object at 0x2bd765ed0>: Failed to establish a new connection: [Errno 8] nodename nor servname provided, or not known'))
2024-01-30 09:16:56,119 INFO    Thread-69 (_run_job):95609 [wandb_run.py:_finish():1962] finishing run adamimos/RRXOR_initial_sweep/f01p000v
2024-01-30 09:16:56,119 INFO    Thread-69 (_run_job):95609 [wandb_run.py:_atexit_cleanup():2202] got exitcode: 0
2024-01-30 09:16:56,120 INFO    Thread-69 (_run_job):95609 [wandb_run.py:_restore():2185] restore
2024-01-30 09:16:56,121 INFO    Thread-69 (_run_job):95609 [wandb_run.py:_restore():2191] restore done
2024-01-30 09:17:20,442 INFO    Thread-69 (_run_job):95609 [wandb_run.py:_footer_history_summary_info():3857] rendering history
2024-01-30 09:17:20,444 INFO    Thread-69 (_run_job):95609 [wandb_run.py:_footer_history_summary_info():3889] rendering summary
2024-01-30 09:17:20,524 INFO    Thread-69 (_run_job):95609 [wandb_run.py:_footer_sync_info():3816] logging synced files
